Workbook
Name Coeffs_111: Coefficients!$C$6
Name Coeffs_112: Coefficients!$N$6
Name Coeffs_113: Coefficients!$Y$6
Name Coeffs_121: Coefficients!$C$17
Name Coeffs_122: Coefficients!$N$17
Name Coeffs_123: Coefficients!$Y$17
Name Coeffs_131: Coefficients!$C$28
Name Coeffs_132: Coefficients!$N$28
Name Coeffs_133: Coefficients!$Y$28
Name Coeffs_141: Coefficients!$C$39
Name Coeffs_142: Coefficients!$N$39
Name Coeffs_143: Coefficients!$Y$39
Name Coeffs_211: Coefficients!$C$50
Name Coeffs_221: Coefficients!$C$61
Name Coeffs_231: Coefficients!$C$72
Name Coeffs_241: Coefficients!$C$83
Name Coeffs_251: Coefficients!$C$94
Name Family: Coefficients!$AI$9:$AI$10
Name FamSelect: Coefficients!$AJ$8
Name Princeton: Coefficients!$AI$13:$AI$16
Name Sex: Coefficients!$AI$29:$AI$31
Name TypeSelect: Coefficients!$AJ$23
Name UN: Coefficients!$AI$17:$AI$21
Name Variant: Coefficients!$AI$24:$AI$26

Sheet Introduction
A1: Estimation of child mortality using data on children ever born and children surviving - Instructions
A3: This method is described at:
A4: http://demographicestimation.iussp.org/content/indirect-estimation-child-mortality
A6: This spreadsheet estimates child mortality from data on the mean number of children ever born and surviving by age of mother, the duration since first birth, or duration since marriage.
A8: Set input parameters
A9: 1 | B9: Enter the country name and data descriptor in the green cell to the right. | C9: Country | D9: México | F9: Malawi
A11: 2 | B11: Record the date of the inquiry in the green cell to the right. | C11: Census date | D11: 43891 | F11: 39617
A14: 3 | B14: Specify the variant of the model to be fitted. | C14: Variant of method | D14: Age of mother
A17: 4 | B17: Set the mortality parameters for the method in the green cells to the right. | C17: Family of model life tables | D17: Princeton
C18: Mortality pattern | D18: West
C20: Sex | D20: Both
C21: Mean age of childbearing | D21: 28
A23: 5 | B23: Place the mean number of children ever born, tabulated according to the variant of the model in cells B5:B11 of the Method sheet. | C23: =IF(ISNA(VLOOKUP(VALUE(RIGHT(Coefficients!AM5,3)),Coefficients!$AI$34:$AI$50,1,FALSE)),"INVALID SELECTION - Please ensure that your choice of variant; family and pattern are consistent.","")
A25: 6 | B25: Place the mean number of children surviving, tabulated according to the variant of the model in cells C5:C11 of the Method sheet.
A27: Results
B28: Estimates of infant mortality, q(1), and child mortality, q(5), are located in cells L5:M10 of the Method sheet.
B29: Time locations of these estimates are located in cells K5:K10 of the Method sheet.

Sheet Coefficients
A1: BY AGE OF MOTHER | L1: BY DURATION SINCE FIRST BIRTH | W1: BY DURATION SINCE MARRIAGE
C3: Conversion of D into q | H3: Time location | N3: Conversion of D into q | S3: Time location | Y3: Conversion of D into q | AD3: Time location
A4: Princeton - North | N4: Princeton - North | Y4: Princeton - North
A5: Age | B5: x | C5: a(x,j) | D5: b(x,j) | E5: c(x,j) | F5: d(x,j) | H5: e(x,j) | I5: f(x,j) | J5: g(x,j) | L5: Duration | M5: x | N5: a(x,j) | O5: b(x,j) | P5: c(x,j) | S5: e(x,j) | T5: f(x,j) | U5: g(x,j) | W5: Duration | X5: x | Y5: a(x,j) | Z5: b(x,j) | AA5: c(x,j) | AD5: e(x,j) | AE5: f(x,j) | AF5: g(x,j) | AH5: =Introduction!D9&" "&TEXT(YEAR(Introduction!D11),"####") -> México 2020 | AM5: ="Coeffs_"&TEXT(100*AJ8+10*AJ12+AJ23,0) -> Coeffs_141
A6: 15-19 | B6: 1 | C6: 1.1119 | D6: -2.9287 | E6: 0.8507 | H6: 1.0921 | I6: 5.4732 | J6: -1.9672 | L6: 0-4 | M6: 2 | N6: 1.198 | O6: -0.1266 | P6: 0.0038 | S6: 1.71 | T6: 1.07 | U6: -0.35 | W6: 0-4 | X6: 2 | Y6: 1.2615 | Z6: -0.534 | AA6: 0.1252 | AD6: 1.0311 | AE6: 1.3149 | AF6: -0.3282 | AH6: Census date | AJ6: =YEAR(Introduction!D11)+YEARFRAC(DATE(YEAR(Introduction!D11)-1,12,31), Introduction!D11,1) -> 2020.1667 | AM6: 0 | AN6: 1 | AO6: 2 | AP6: 3 | AR6: 5 | AS6: 6 | AT6: 7 | AV6: Metric
A7: 20-24 | B7: 2 | C7: 1.239 | D7: -0.6865 | E7: -0.2745 | H7: 1.3207 | I7: 5.3751 | J7: 0.2133 | L7: 5-9 | M7: 5 | N7: 1.2248 | O7: -0.1919 | P7: -0.087 | S7: 2.16 | T7: 4.36 | U7: 0.12 | W7: 5-9 | X7: 3 | Y7: 1.1957 | Z7: -0.4103 | AA7: -0.093 | AD7: 1.6964 | AE7: 4.5147 | AF7: -0.016 | AL7: 0 | AM7: =OFFSET(INDIRECT($AM$5),$AL7,AM$6) -> 1.1415 | AN7: =OFFSET(INDIRECT($AM$5),$AL7,AN$6) -> -2.707 | AO7: =OFFSET(INDIRECT($AM$5),$AL7,AO$6) -> 0.7663 | AP7: =OFFSET(INDIRECT($AM$5),$AL7,AP$6) -> 0 | AR7: =OFFSET(INDIRECT($AM$5),$AL7,AR$6) -> 1.097 | AS7: =OFFSET(INDIRECT($AM$5),$AL7,AS$6) -> 5.5628 | AT7: =OFFSET(INDIRECT($AM$5),$AL7,AT$6) -> -1.9956 | AV7: =OFFSET(INDIRECT($AM$5),AL7,-1) -> 1
A8: 25-29 | B8: 3 | C8: 1.1884 | D8: 0.0421 | E8: -0.5156 | H8: 1.5996 | I8: 2.6268 | J8: 4.3701 | L8: 10-14 | M8: 5 | N8: 1.2076 | O8: -0.0105 | P8: -0.2911 | S8: 0.66 | T8: 3.5 | U8: 6.65 | W8: 10-14 | X8: 5 | Y8: 1.3067 | Z8: -0.0103 | AA8: -0.4618 | AD8: 1.4285 | AE8: 3.2684 | AF8: 4.4073 | AH8: Model family | AJ8: =MATCH(Introduction!D17,Family,0) -> 1 | AL8: 1 | AM8: =OFFSET(INDIRECT($AM$5),$AL8,AM$6) -> 1.2563 | AN8: =OFFSET(INDIRECT($AM$5),$AL8,AN$6) -> -0.5381 | AO8: =OFFSET(INDIRECT($AM$5),$AL8,AO$6) -> -0.2637 | AP8: =OFFSET(INDIRECT($AM$5),$AL8,AP$6) -> 0 | AR8: =OFFSET(INDIRECT($AM$5),$AL8,AR$6) -> 1.3062 | AS8: =OFFSET(INDIRECT($AM$5),$AL8,AS$6) -> 5.5677 | AT8: =OFFSET(INDIRECT($AM$5),$AL8,AT$6) -> 0.2962 | AV8: =OFFSET(INDIRECT($AM$5),AL8,-1) -> 2
A9: 30-34 | B9: 5 | C9: 1.2046 | D9: 0.3037 | E9: -0.5656 | H9: 2.0779 | I9: -1.7908 | J9: 9.4126 | L9: 15-19 | M9: 5 | N9: 1.203 | O9: 0.0896 | P9: -0.4265 | S9: -1.96 | T9: -0.9 | U9: 17.66 | W9: 15-19 | X9: 10 | Y9: 1.4701 | Z9: 0.1763 | AA9: -0.7268 | AD9: -0.0753 | AE9: -1.08 | AF9: 12.9281 | AI9: Princeton | AL9: 2 | AM9: =OFFSET(INDIRECT($AM$5),$AL9,AM$6) -> 1.1851 | AN9: =OFFSET(INDIRECT($AM$5),$AL9,AN$6) -> 0.0633 | AO9: =OFFSET(INDIRECT($AM$5),$AL9,AO$6) -> -0.4177 | AP9: =OFFSET(INDIRECT($AM$5),$AL9,AP$6) -> 0 | AR9: =OFFSET(INDIRECT($AM$5),$AL9,AR$6) -> 1.5305 | AS9: =OFFSET(INDIRECT($AM$5),$AL9,AS$6) -> 2.5528 | AT9: =OFFSET(INDIRECT($AM$5),$AL9,AT$6) -> 4.8962 | AV9: =OFFSET(INDIRECT($AM$5),AL9,-1) -> 3
A10: 35-39 | B10: 10 | C10: 1.2586 | D10: 0.4236 | E10: -0.5898 | H10: 2.7705 | I10: -7.3403 | J10: 14.9352 | L10: 20-24 | M10: 10 | N10: 1.3292 | O10: 0.1598 | P10: -0.5778 | S10: -3.85 | T10: -6.42 | U10: 28.94 | W10: 20-24 | X10: 15 | Y10: 1.5039 | Z10: 0.0039 | AA10: -0.7071 | AD10: -1.9749 | AE10: -3.4773 | AF10: 21.3318 | AI10: UN | AL10: 3 | AM10: =OFFSET(INDIRECT($AM$5),$AL10,AM$6) -> 1.172 | AN10: =OFFSET(INDIRECT($AM$5),$AL10,AN$6) -> 0.2341 | AO10: =OFFSET(INDIRECT($AM$5),$AL10,AO$6) -> -0.4272 | AP10: =OFFSET(INDIRECT($AM$5),$AL10,AP$6) -> 0 | AR10: =OFFSET(INDIRECT($AM$5),$AL10,AR$6) -> 1.9991 | AS10: =OFFSET(INDIRECT($AM$5),$AL10,AS$6) -> -2.4261 | AT10: =OFFSET(INDIRECT($AM$5),$AL10,AT$6) -> 10.4282 | AV10: =OFFSET(INDIRECT($AM$5),AL10,-1) -> 5
A11: 40-44 | B11: 15 | C11: 1.224 | D11: 0.4222 | E11: -0.5456 | H11: 4.152 | I11: -12.2448 | J11: 19.2349 | W11: 25-29 | X11: 20 | Y11: 1.4798 | Z11: -0.2487 | AA11: -0.5582 | AD11: -2.1888 | AE11: 0.6124 | AF11: 23.9376 | AL11: 4 | AM11: =OFFSET(INDIRECT($AM$5),$AL11,AM$6) -> 1.1865 | AN11: =OFFSET(INDIRECT($AM$5),$AL11,AN$6) -> 0.308 | AO11: =OFFSET(INDIRECT($AM$5),$AL11,AO$6) -> -0.4452 | AP11: =OFFSET(INDIRECT($AM$5),$AL11,AP$6) -> 0 | AR11: =OFFSET(INDIRECT($AM$5),$AL11,AR$6) -> 2.7632 | AS11: =OFFSET(INDIRECT($AM$5),$AL11,AS$6) -> -8.4065 | AT11: =OFFSET(INDIRECT($AM$5),$AL11,AT$6) -> 16.1787 | AV11: =OFFSET(INDIRECT($AM$5),AL11,-1) -> 10
A12: 45-49 | B12: 20 | C12: 1.1772 | D12: 0.3486 | E12: -0.4624 | H12: 6.965 | I12: -13.916 | J12: 19.9542 | AH12: Model pattern | AJ12: =MATCH(Introduction!D18,IF(AJ8=1,Princeton,UN),0) -> 4 | AL12: 5 | AM12: =OFFSET(INDIRECT($AM$5),$AL12,AM$6) -> 1.1746 | AN12: =OFFSET(INDIRECT($AM$5),$AL12,AN$6) -> 0.3314 | AO12: =OFFSET(INDIRECT($AM$5),$AL12,AO$6) -> -0.4537 | AP12: =OFFSET(INDIRECT($AM$5),$AL12,AP$6) -> 0 | AR12: =OFFSET(INDIRECT($AM$5),$AL12,AR$6) -> 4.3468 | AS12: =OFFSET(INDIRECT($AM$5),$AL12,AS$6) -> -13.2436 | AT12: =OFFSET(INDIRECT($AM$5),$AL12,AT$6) -> 20.199 | AV12: =OFFSET(INDIRECT($AM$5),AL12,-1) -> 15
AI13: North | AL13: 6 | AM13: =OFFSET(INDIRECT($AM$5),$AL13,AM$6) -> 1.1639 | AN13: =OFFSET(INDIRECT($AM$5),$AL13,AN$6) -> 0.319 | AO13: =OFFSET(INDIRECT($AM$5),$AL13,AO$6) -> -0.4435 | AP13: =OFFSET(INDIRECT($AM$5),$AL13,AP$6) -> 0 | AR13: =OFFSET(INDIRECT($AM$5),$AL13,AR$6) -> 7.5242 | AS13: =OFFSET(INDIRECT($AM$5),$AL13,AS$6) -> -14.2013 | AT13: =OFFSET(INDIRECT($AM$5),$AL13,AT$6) -> 20.0162 | AV13: =OFFSET(INDIRECT($AM$5),AL13,-1) -> 20
AI14: South
A15: Princeton - South | N15: Princeton - South | Y15: Princeton - South | AI15: East | AM15: Selected LT
A16: Age | B16: x | C16: a(x,j) | D16: b(x,j) | E16: c(x,j) | F16: d(x,j) | H16: e(x,j) | I16: f(x,j) | J16: g(x,j) | L16: Duration | M16: x | N16: a(x,j) | O16: b(x,j) | P16: c(x,j) | S16: e(x,j) | T16: f(x,j) | U16: g(x,j) | W16: Duration | X16: x | Y16: a(x,j) | Z16: b(x,j) | AA16: c(x,j) | AD16: e(x,j) | AE16: f(x,j) | AF16: g(x,j) | AI16: West | AM16: x | AN16: logit l(x)
A17: 15-19 | B17: 1 | C17: 1.0819 | D17: -3.0005 | E17: 0.8689 | H17: 1.09 | I17: 5.4443 | J17: -1.9721 | L17: 0-4 | M17: 2 | N17: 1.1705 | O17: -0.1461 | P17: 0.0051 | S17: 1.68 | T17: 0.96 | U17: -0.32 | W17: 0-4 | X17: 2 | Y17: 1.3103 | Z17: -0.5856 | AA17: 0.1367 | AD17: 1.0202 | AE17: 1.3064 | AF17: -0.3297 | AI17: Latin America | AM17: 0
A18: 20-24 | B18: 2 | C18: 1.2846 | D18: -0.6181 | E18: -0.3024 | H18: 1.3079 | I18: 5.5568 | J18: 0.2021 | L18: 5-9 | M18: 5 | N18: 1.3166 | O18: -0.3157 | P18: -0.0971 | S18: 2.29 | T18: 3.84 | U18: -0.01 | W18: 5-9 | X18: 3 | Y18: 1.2309 | Z18: -0.3463 | AA18: -0.1073 | AD18: 1.6601 | AE18: 4.5105 | AF18: -0.0335 | AI18: Chile | AM18: 1 | AN18: =HLOOKUP(Coefficients!$AJ$8*100+Coefficients!$AJ$12*10+Coefficients!$AJ$28,'Model LTs'!$A$2:$AB$13,5,FALSE) -> -1.2920085
A19: 25-29 | B19: 3 | C19: 1.2223 | D19: 0.0851 | E19: -0.4704 | H19: 1.5173 | I19: 2.6755 | J19: 4.7471 | L19: 10-14 | M19: 5 | N19: 1.2952 | O19: -0.0423 | P19: -0.4295 | S19: 1.19 | T19: 3.45 | U19: 5.41 | W19: 10-14 | X19: 5 | Y19: 1.2774 | Z19: 0.0336 | AA19: -0.3987 | AD19: 1.2146 | AE19: 3.4684 | AF19: 4.9524 | AI19: South Asian | AM19: 2 | AN19: =HLOOKUP(Coefficients!$AJ$8*100+Coefficients!$AJ$12*10+Coefficients!$AJ$28,'Model LTs'!$A$2:$AB$13,6,FALSE) -> -1.199382
A20: 30-34 | B20: 5 | C20: 1.1905 | D20: 0.2631 | E20: -0.4487 | H20: 1.9399 | I20: -2.2739 | J20: 10.3876 | L20: 15-19 | M20: 5 | N20: 1.2836 | O20: 0.1308 | P20: -0.6496 | S20: -1.01 | T20: -0.18 | U20: 15.03 | W20: 15-19 | X20: 10 | Y20: 1.3493 | Z20: 0.1366 | AA20: -0.5403 | AD20: -0.6454 | AE20: -1.6045 | AF20: 14.6773 | AI20: Far East | AM20: 3 | AN20: =HLOOKUP(Coefficients!$AJ$8*100+Coefficients!$AJ$12*10+Coefficients!$AJ$28,'Model LTs'!$A$2:$AB$13,7,FALSE) -> -1.1592413
A21: 35-39 | B21: 10 | C21: 1.1911 | D21: 0.3152 | E21: -0.4291 | H21: 2.6157 | I21: -8.4819 | J21: 16.5153 | L21: 20-24 | M21: 10 | N21: 1.5269 | O21: 0.2659 | P21: -0.9174 | S21: -2.68 | T21: -5.06 | U21: 25.21 | W21: 20-24 | X21: 15 | Y21: 1.3592 | Z21: -0.0315 | AA21: -0.4944 | AD21: -2.9104 | AE21: -4.1352 | AF21: 24.0072 | AI21: General | AM21: 4 | AN21: =HLOOKUP(Coefficients!$AJ$8*100+Coefficients!$AJ$12*10+Coefficients!$AJ$28,'Model LTs'!$A$2:$AB$13,8,FALSE) -> -1.1338485
A22: 40-44 | B22: 15 | C22: 1.1564 | D22: 0.3017 | E22: -0.3958 | H22: 4.0794 | I22: -13.8308 | J22: 21.1866 | W22: 25-29 | X22: 20 | Y22: 1.3532 | Z22: -0.1978 | AA22: -0.4099 | AD22: -3.1641 | AE22: 1.2106 | AF22: 26.3515 | AM22: 5 | AN22: =HLOOKUP(Coefficients!$AJ$8*100+Coefficients!$AJ$12*10+Coefficients!$AJ$28,'Model LTs'!$A$2:$AB$13,9,FALSE) -> -1.1143193
A23: 45-49 | B23: 20 | C23: 1.1307 | D23: 0.2596 | E23: -0.3538 | H23: 7.1796 | I23: -15.388 | J23: 21.7892 | AH23: Model variant | AJ23: =MATCH(Introduction!D14,Variant,0) -> 1 | AM23: 10 | AN23: =HLOOKUP(Coefficients!$AJ$8*100+Coefficients!$AJ$12*10+Coefficients!$AJ$28,'Model LTs'!$A$2:$AB$13,10,FALSE) -> -1.064845
AI24: Age of mother | AM24: 15 | AN24: =HLOOKUP(Coefficients!$AJ$8*100+Coefficients!$AJ$12*10+Coefficients!$AJ$28,'Model LTs'!$A$2:$AB$13,11,FALSE) -> -1.029312
AI25: Duration since first birth | AM25: 20 | AN25: =HLOOKUP(Coefficients!$AJ$8*100+Coefficients!$AJ$12*10+Coefficients!$AJ$28,'Model LTs'!$A$2:$AB$13,12,FALSE) -> -0.97893415
A26: Princeton - East | N26: Princeton - East | Y26: Princeton - East | AI26: Duration since marriage
A27: Age | B27: x | C27: a(x,j) | D27: b(x,j) | E27: c(x,j) | F27: d(x,j) | H27: e(x,j) | I27: f(x,j) | J27: g(x,j) | L27: Duration | M27: x | N27: a(x,j) | O27: b(x,j) | P27: c(x,j) | S27: e(x,j) | T27: f(x,j) | U27: g(x,j) | W27: Duration | X27: x | Y27: a(x,j) | Z27: b(x,j) | AA27: c(x,j) | AD27: e(x,j) | AE27: f(x,j) | AF27: g(x,j)
A28: 15-19 | B28: 1 | C28: 1.1461 | D28: -2.2536 | E28: 0.6259 | H28: 1.0959 | I28: 5.5864 | J28: -1.9949 | L28: 0-4 | M28: 2 | N28: 1.2182 | O28: -0.1809 | P28: 0.0214 | S28: 1.68 | T28: 0.99 | U28: -0.33 | W28: 0-4 | X28: 2 | Y28: 1.2299 | Z28: -0.3998 | AA28: 0.091 | AD28: 1.038 | AE28: 1.4213 | AF28: -0.3545 | AH28: Sex | AJ28: =MATCH(Introduction!D20,Sex,0) -> 3
A29: 20-24 | B29: 2 | C29: 1.2231 | D29: -0.4301 | E29: -0.2245 | H29: 1.2921 | I29: 5.5897 | J29: 0.3631 | L29: 5-9 | M29: 5 | N29: 1.2769 | O29: -0.2268 | P29: -0.1052 | S29: 2.19 | T29: 4.28 | U29: 0.02 | W29: 5-9 | X29: 3 | Y29: 1.1611 | Z29: -0.2451 | AA29: -0.0797 | AD29: 1.6441 | AE29: 4.7042 | AF29: 0.0642 | AI29: Male
A30: 25-29 | B30: 3 | C30: 1.1593 | D30: 0.0581 | E30: -0.3479 | H30: 1.5021 | I30: 2.4692 | J30: 5.0927 | L30: 10-14 | M30: 5 | N30: 1.2731 | O30: 0.0005 | P30: -0.372 | S30: 0.71 | T30: 3.63 | U30: 6.36 | W30: 10-14 | X30: 5 | Y30: 1.2036 | Z30: 0.0171 | AA30: -0.2992 | AD30: 1.1068 | AE30: 3.3032 | AF30: 5.4464 | AI30: Female
A31: 30-34 | B31: 5 | C31: 1.1404 | D31: 0.1991 | E31: -0.3487 | H31: 1.9347 | I31: -2.6419 | J31: 10.8533 | L31: 15-19 | M31: 5 | N31: 1.2585 | O31: 0.1216 | P31: -0.5013 | S31: -1.96 | T31: -0.71 | U31: 17.42 | W31: 15-19 | X31: 10 | Y31: 1.2773 | Z31: 0.1015 | AA31: -0.4276 | AD31: -0.8678 | AE31: -1.9683 | AF31: 15.5187 | AI31: Both
A32: 35-39 | B32: 10 | C32: 1.154 | D32: 0.2511 | E32: -0.3506 | H32: 2.6197 | I32: -8.9693 | J32: 17.0981 | L32: 20-24 | M32: 10 | N32: 1.341 | O32: 0.1749 | P32: -0.5964 | S32: -4.06 | T32: -6.35 | U32: 29.14 | W32: 20-24 | X32: 15 | Y32: 1.3014 | Z32: -0.0219 | AA32: -0.4195 | AD32: -3.2154 | AE32: -4.1123 | AF32: 24.8624
A33: 40-44 | B33: 15 | C33: 1.1336 | D33: 0.2556 | E33: -0.3428 | H33: 4.1317 | I33: -14.355 | J33: 21.8247 | W33: 25-29 | X33: 20 | Y33: 1.316 | Z33: -0.163 | AA33: -0.3751 | AD33: -3.3885 | AE33: 1.6746 | AF33: 26.9798 | AH33: Valid combinations | AJ33: =VLOOKUP(100*AJ8+10*AJ12+AJ23,$AI$34:$AI$50,1,FALSE) -> 141
A34: 45-49 | B34: 20 | C34: 1.1201 | D34: 0.2362 | E34: -0.3268 | H34: 7.3657 | I34: -15.8083 | J34: 22.3005 | AI34: 111
AI35: 121
AI36: 131
A37: Princeton - West | N37: Princeton - West | Y37: Princeton - West | AI37: 141
A38: Age | B38: x | C38: a(x,j) | D38: b(x,j) | E38: c(x,j) | F38: d(x,j) | H38: e(x,j) | I38: f(x,j) | J38: g(x,j) | L38: Duration | M38: x | N38: a(x,j) | O38: b(x,j) | P38: c(x,j) | S38: e(x,j) | T38: f(x,j) | U38: g(x,j) | W38: Duration | X38: x | Y38: a(x,j) | Z38: b(x,j) | AA38: c(x,j) | AD38: e(x,j) | AE38: f(x,j) | AF38: g(x,j) | AI38: 211
A39: 15-19 | B39: 1 | C39: 1.1415 | D39: -2.707 | E39: 0.7663 | H39: 1.097 | I39: 5.5628 | J39: -1.9956 | L39: 0-4 | M39: 2 | N39: 1.2049 | O39: -0.1553 | P39: 0.0135 | S39: 1.7 | T39: 1.03 | U39: -0.34 | W39: 0-4 | X39: 2 | Y39: 1.2584 | Z39: -0.4683 | AA39: 0.108 | AD39: 1.0349 | AE39: 1.3714 | AF39: -0.339 | AI39: 221
A40: 20-24 | B40: 2 | C40: 1.2563 | D40: -0.5381 | E40: -0.2637 | H40: 1.3062 | I40: 5.5677 | J40: 0.2962 | L40: 5-9 | M40: 5 | N40: 1.2573 | O40: -0.2266 | P40: -0.0944 | S40: 2.2 | T40: 4.2 | U40: 0.06 | W40: 5-9 | X40: 3 | Y40: 1.1841 | Z40: -0.3006 | AA40: -0.0892 | AD40: 1.6654 | AE40: 4.4588 | AF40: 0.0233 | AI40: 231
A41: 25-29 | B41: 3 | C41: 1.1851 | D41: 0.0633 | E41: -0.4177 | H41: 1.5305 | I41: 2.5528 | J41: 4.8962 | L41: 10-14 | M41: 5 | N41: 1.2431 | O41: -0.023 | P41: -0.3409 | S41: 0.86 | T41: 3.47 | U41: 6.21 | W41: 10-14 | X41: 5 | Y41: 1.2446 | Z41: 0.0131 | AA41: -0.3555 | AD41: 1.2109 | AE41: 3.3291 | AF41: 5.1402 | AI41: 241
...

Sheet Model LTs
A1: Model LTs | B1: logits with e0 = 60
B2: 111 | C2: 112 | D2: 113 | E2: 121 | F2: 122 | G2: 123 | H2: 131 | I2: 132 | J2: 133 | K2: 141 | L2: 142 | M2: 143 | N2: 211 | O2: 212 | P2: 213 | Q2: 221 | R2: 222 | S2: 223 | T2: 231 | U2: 232 | V2: 233 | W2: 241 | X2: 242 | Y2: 243 | Z2: 251 | AA2: 252 | AB2: 253
B3: Princeton North | E3: Princeton South | H3: Princeton East | K3: Princeton West | N3: UN Latin American | Q3: UN Chilean | T3: UN South Asian | W3: UN Far Eastern | Z3: UN General
A4: x | B4: Males | C4: Females | D4: Combined | E4: Males | F4: Females | G4: Combined | H4: Males | I4: Females | J4: Combined | K4: Males | L4: Females | M4: Combined | N4: Males | O4: Females | P4: Combined | Q4: Males | R4: Females | S4: Combined | T4: Males | U4: Females | V4: Combined | W4: Males | X4: Females | Y4: Combined | Z4: Males | AA4: Females | AB4: Combined
A5: 0
A6: 1 | B6: -1.3391919 | C6: -1.3205377 | D6: -1.3300167 | E6: -1.149543 | F6: -1.1287565 | G6: -1.1393153 | H6: -1.1995667 | I6: -1.1590577 | J6: -1.1794669 | K6: -1.3008883 | L6: -1.2828283 | M6: -1.2920085 | N6: -1.2244025 | O6: -1.2375303 | P6: -1.23077 | Q6: -1.1881811 | R6: -1.1106269 | S6: -1.149121 | T6: -1.1633365 | U6: -1.1378733 | V6: -1.1507829 | W6: -1.4833929 | X6: -1.3772257 | Y6: -1.4290934 | Z6: -1.2808738 | AA6: -1.2702343 | AB6: -1.2756596
A7: 2 | B7: -1.2482714 | C7: -1.2060903 | D7: -1.2273209 | E7: -1.0529219 | F7: -1.0009991 | G7: -1.0270731 | H7: -1.1377254 | I7: -1.073353 | J7: -1.1054932 | K7: -1.2215537 | L7: -1.1769512 | M7: -1.199382 | N7: -1.1230472 | O7: -1.1005761 | P7: -1.1119841 | Q7: -1.1426713 | R7: -1.0454 | S7: -1.0933348 | T7: -1.0463869 | U7: -1.0078054 | V7: -1.0272792 | W7: -1.4168729 | X7: -1.2912754 | Y7: -1.3521595 | Z7: -1.1994286 | AA7: -1.1587987 | AB7: -1.1792678
A8: 3 | B8: -1.1910199 | C8: -1.1415199 | D8: -1.1663695 | E8: -1.0116418 | F8: -0.94932383 | G8: -0.98051169 | H8: -1.1122189 | I8: -1.0396889 | J8: -1.0757977 | K8: -1.1859677 | L8: -1.1323859 | M8: -1.1592413 | N8: -1.0763916 | O8: -1.039815 | P8: -1.0582869 | Q8: -1.1204664 | R8: -1.0161031 | S8: -1.0674115 | T8: -0.99614964 | U8: -0.95267015 | V8: -0.97458547 | W8: -1.3824459 | X8: -1.2510803 | Y8: -1.3146345 | Z8: -1.1601037 | AA8: -1.1075443 | AB8: -1.1339041
A9: 4 | B9: -1.1495156 | C9: -1.0955047 | D9: -1.1225794 | E9: -0.99004099 | F9: -0.92335584 | G9: -0.95668616 | H9: -1.0959154 | I9: -1.0182341 | J9: -1.0568391 | K9: -1.1622355 | L9: -1.1053872 | M9: -1.1338485 | N9: -1.0483131 | O9: -1.0046334 | P9: -1.0266376 | Q9: -1.1064494 | R9: -0.99875 | S9: -1.0516453 | T9: -0.9677394 | U9: -0.92208657 | V9: -0.94508558 | W9: -1.3597145 | X9: -1.2265312 | Y9: -1.2909394 | Z9: -1.1355662 | AA9: -1.0767437 | AB9: -1.1061781
A10: 5 | B10: -1.1185632 | C10: -1.0613253 | D10: -1.0899898 | E10: -0.97803105 | F10: -0.90879111 | G10: -0.94337274 | H10: -1.0839282 | I10: -1.0034528 | J10: -1.0434107 | K10: -1.1443837 | L10: -1.0842444 | M10: -1.1143193 | N10: -1.0292629 | O10: -0.98147967 | P10: -1.0055181 | Q10: -1.0965956 | R10: -0.98713579 | S10: -1.0408706 | T10: -0.94947888 | U10: -0.90273095 | V10: -0.92627697 | W10: -1.3430952 | X10: -1.2095785 | Y10: -1.2741583 | Z10: -1.1183427 | AA10: -1.0557703 | AB10: -1.0870409
A11: 10 | B11: -1.0393563 | C11: -0.97867737 | D11: -1.0090526 | E11: -0.94784308 | F11: -0.87426675 | G11: -0.91097597 | H11: -1.0472539 | I11: -0.96210277 | J11: -1.0043335 | K11: -1.0968312 | L11: -1.0329082 | M11: -1.064845 | N11: -0.98369901 | O11: -0.93040264 | P11: -0.95717334 | Q11: -1.071048 | R11: -0.96012757 | S11: -1.0145804 | T11: -0.91071239 | U11: -0.86341317 | V11: -0.88724264 | W11: -1.2967451 | X11: -1.1678086 | Y11: -1.2303496 | Z11: -1.0743949 | AA11: -1.0059691 | AB11: -1.0401061
A12: 15 | B12: -0.99810318 | C12: -0.93456379 | D12: -0.96635457 | E12: -0.92724295 | F12: -0.85272015 | G12: -0.88990311 | H12: -1.0232405 | I12: -0.93688771 | J12: -0.97971407 | K12: -1.0631132 | L12: -0.99562585 | M12: -1.029312 | N12: -0.95845256 | O12: -0.90544375 | P12: -0.93208089 | Q12: -1.0502865 | R12: -0.93957838 | S12: -0.9939579 | T12: -0.89415624 | U12: -0.84720718 | V12: -0.87086768 | W12: -1.2584277 | X12: -1.1373287 | Y12: -1.1963047 | Z12: -1.0466409 | AA12: -0.97788284 | AB12: -1.0121946
A13: 20 | B13: -0.94163339 | C13: -0.88577608 | D13: -0.91382222 | E13: -0.89806981 | F13: -0.82207222 | G13: -0.8599929 | H13: -0.98210627 | I13: -0.90144694 | J13: -0.94156372 | K13: -1.0130423 | L13: -0.94491044 | M13: -0.97893415 | N13: -0.92315127 | O13: -0.87353504 | P13: -0.89850801 | Q13: -1.015086 | R13: -0.90716031 | S13: -0.96027266 | T13: -0.87450043 | U13: -0.82539225 | V13: -0.85012871 | W13: -1.2020972 | X13: -1.0804887 | Y13: -1.1397671 | Z13: -1.0066774 | AA13: -0.93810587 | AB13: -0.97234684

Sheet Decrementos Múltiples San Luis 
B2: Hombres, 2019
B3: Age x | C3: n | D3: nDx | E3: nDxi | I3: nqx | K3: e0 | M3: nqx_i | O3: ndx_i | Q3: L | R3: T | S3: e0_i | T3: diff
B4: 0 | C4: 1 | D4: =def_sl!D21 -> 251.2433 | E4: =def_pro_homicidios_sl!D425 -> 1.0043478 | F4: =(D4-E4)/D4 -> 0.99600249 | G4: =lt_sl!G21 -> 100000 | H4: =1-lt_sl!E21 -> 0.998187 | I4: =1-H4 -> 0.001813 | J4: =lt_sl!F21 -> 0.05 | K4: =lt_sl!K21 -> 75.44 | L4: =H4^F4 -> 0.99819424 | M4: =1-L4 -> 0.0018057591 | N4: 100000 | O4: =N4*M4 -> 180.57591 | P4: =C4+(F4*(I4/M4)*(J4-C4)) -> 0.050003445 | Q4: =(C4*N5)+(P4*O4) -> 99828.454 | R4: =R5+Q4 -> 7647882.1 | S4: =R4/N4 -> 76.478821 | T4: =S4-K4 -> 1.0388215
B5: 1 | C5: 4 | D5: =def_sl!D22 -> 57.010522 | E5: =def_pro_homicidios_sl!D426 -> 0 | F5: =(D5-E5)/D5 -> 1 | G5: =lt_sl!G22 -> 99819 | H5: =1-lt_sl!E22 -> 0.997618 | I5: =1-H5 -> 0.002382 | J5: =lt_sl!F22 -> 1.65 | K5: =lt_sl!K22 -> 74.58 | L5: =H5^F5 -> 0.997618 | M5: =1-L5 -> 0.002382 | N5: =N4*L4 -> 99819.424 | O5: =N5*M5 -> 237.76987 | P5: =C5+(F5*(I5/M5)*(J5-C5)) -> 1.65 | Q5: =(C5*N6)+(P5*O5) -> 398718.94 | R5: =R6+Q5 -> 7548053.7 | S5: =R5/N5 -> 75.617083 | T5: =S5-K5 -> 1.0370832 | V5: Número de años que se espera que viva un hombre de 0 años hasta llegar a los 85 años.
B6: 5 | C6: 5 | D6: =def_sl!D23 -> 32.005723 | E6: 0 | F6: =(D6-E6)/D6 -> 1 | G6: =lt_sl!G23 -> 99581 | H6: =1-lt_sl!E23 -> 0.998709 | I6: =1-H6 -> 0.001291 | J6: =lt_sl!F23 -> 2.5 | K6: =lt_sl!K23 -> 70.75 | L6: =H6^F6 -> 0.998709 | M6: =1-L6 -> 0.001291 | N6: =N5*L5 -> 99581.654 | O6: =N6*M6 -> 128.55992 | P6: =C6+(F6*(I6/M6)*(J6-C6)) -> 2.5 | Q6: =(C6*N7)+(P6*O6) -> 497586.87 | R6: =R7+Q6 -> 7149334.8 | S6: =R6/N6 -> 71.793693 | T6: =S6-K6 -> 1.0436935
B7: 10 | C7: 5 | D7: =def_sl!D24 -> 42.008167 | E7: =def_pro_homicidios_sl!D427 -> 3.0130435 | F7: =(D7-E7)/D7 -> 0.92827482 | G7: =lt_sl!G24 -> 99452 | H7: =1-lt_sl!E24 -> 0.998371 | I7: =1-H7 -> 0.001629 | J7: =lt_sl!F24 -> 2.5 | K7: =lt_sl!K24 -> 65.84 | L7: =H7^F7 -> 0.99848775 | M7: =1-L7 -> 0.0015122481 | N7: =N6*L6 -> 99453.094 | O7: =N7*M7 -> 150.39775 | P7: =(((-5/24)*O6)+((2.5)*O7)+((5/24)*O8))/O7 -> 2.9511349 | Q7: =(C7*N8)+(P7*O7) -> 496957.33 | R7: =R8+Q7 -> 6651747.9 | S7: =R7/N7 -> 66.883267 | T7: =S7-K7 -> 1.0432673
B8: 15 | C8: 5 | D8: =def_sl!D25 -> 165.02948 | E8: =def_pro_homicidios_sl!D428 -> 47.204348 | F8: =(D8-E8)/D8 -> 0.71396415 | G8: =lt_sl!G25 -> 99290 | H8: =1-lt_sl!E25 -> 0.993599 | I8: =1-H8 -> 0.006401 | J8: =lt_sl!F25 -> 2.5 | K8: =lt_sl!K25 -> 60.94 | L8: =H8^F8 -> 0.99542572 | M8: =1-L8 -> 0.0045742798 | N8: =N7*L7 -> 99302.697 | O8: =N8*M8 -> 454.23832 | P8: =(((-5/24)*O7)+((2.5)*O8)+((5/24)*O9))/O8 -> 2.7906922 | Q8: =(C8*N9)+(P8*O8) -> 495509.93 | R8: =R9+Q8 -> 6154790.6 | S8: =R8/N8 -> 61.980095 | T8: =S8-K8 -> 1.0400949 | V8: Sin COVID | W8: Con COVID
B9: 20 | C9: 5 | D9: =def_sl!D26 -> 246.04596 | E9: =def_pro_homicidios_sl!D429 -> 66.286957 | F9: =(D9-E9)/D9 -> 0.73059116 | G9: =lt_sl!G26 -> 98655 | H9: =1-lt_sl!E26 -> 0.989157 | I9: =1-H9 -> 0.010843 | J9: =lt_sl!F26 -> 2.5 | K9: =lt_sl!K26 -> 56.32 | L9: =H9^F9 -> 0.99206658 | M9: =1-L9 -> 0.007933424 | N9: =N8*L8 -> 98848.458 | O9: =N9*M9 -> 784.20673 | P9: =(((-5/24)*O8)+((2.5)*O9)+((5/24)*O10))/O9 -> 2.6144178 | Q9: =(C9*N10)+(P9*O9) -> 492371.5 | R9: =R10+Q9 -> 5659280.6 | S9: =R9/N9 -> 57.252088 | T9: =S9-K9 -> 0.932088 | V9: =([1]TV!M53-[1]TV!M71)/[1]TV!J53 -> 66.401396 | W9: =(R4-R22)/N4 -> 73.827836
B10: 25 | C10: 5 | D10: =def_sl!D27 -> 269.04959 | E10: =def_pro_homicidios_sl!D430 -> 79.343478 | F10: =(D10-E10)/D10 -> 0.7050972 | G10: =lt_sl!G27 -> 97585 | H10: =1-lt_sl!E27 -> 0.987226 | I10: =1-H10 -> 0.012774 | J10: =lt_sl!F27 -> 2.5 | K10: =lt_sl!K27 -> 51.91 | L10: =H10^F10 -> 0.99097603 | M10: =1-L10 -> 0.0090239707 | N10: =N9*L9 -> 98064.252 | O10: =N10*M10 -> 884.92894 | P10: =(((-5/24)*O9)+((2.5)*O10)+((5/24)*O11))/O10 -> 2.5207478 | Q10: =(C10*N11)+(P10*O10) -> 488127.3 | R10: =R11+Q10 -> 5166909.1 | S10: =R10/N10 -> 52.689018 | T10: =S10-K10 -> 0.77901816 | V10: Diff | W10: =W9-V9 -> 7.4264392
B11: 30 | C11: 5 | D11: =def_sl!D28 -> 235.04444 | E11: =def_pro_homicidios_sl!D431 -> 62.269565 | F11: =(D11-E11)/D11 -> 0.73507323 | G11: =lt_sl!G28 -> 96339 | H11: =1-lt_sl!E28 -> 0.987808 | I11: =1-H11 -> 0.012192 | J11: =lt_sl!F28 -> 2.5 | K11: =lt_sl!K28 -> 47.55 | L11: =H11^F11 -> 0.99102344 | M11: =1-L11 -> 0.0089765613 | N11: =N10*L10 -> 97179.323 | O11: =N11*M11 -> 872.33615 | P11: =(((-5/24)*O10)+((2.5)*O11)+((5/24)*O12))/O11 -> 2.5491533 | Q11: =(C11*N12)+(P11*O11) -> 483758.65 | R11: =R12+Q11 -> 4678781.8 | S11: =R11/N11 -> 48.145858 | T11: =S11-K11 -> 0.59585767
B12: 35 | C12: 5 | D12: =def_sl!D29 -> 257.54889 | E12: =def_pro_homicidios_sl!D432 -> 52.226087 | F12: =(D12-E12)/D12 -> 0.79721874 | G12: =lt_sl!G29 -> 95164 | H12: =1-lt_sl!E29 -> 0.985814 | I12: =1-H12 -> 0.014186 | J12: =lt_sl!F29 -> 2.5 | K12: =lt_sl!K29 -> 43.11 | L12: =H12^F12 -> 0.9886743 | M12: =1-L12 -> 0.011325705 | N12: =N11*L11 -> 96306.986 | O12: =N12*M12 -> 1090.7445 | P12: =(((-5/24)*O11)+((2.5)*O12)+((5/24)*O13))/O12 -> 2.6289768 | Q12: =(C12*N13)+(P12*O12) -> 478948.75 | R12: =R13+Q12 -> 4195023.2 | S12: =R12/N12 -> 43.558867 | T12: =S12-K12 -> 0.44886668
B13: 40 | C13: 5 | D13: =def_sl!D30 -> 316.56042 | E13: =def_pro_homicidios_sl!D433 -> 40.173913 | F13: =(D13-E13)/D13 -> 0.87309243 | G13: =lt_sl!G30 -> 93814 | H13: =1-lt_sl!E30 -> 0.981406 | I13: =1-H13 -> 0.018594 | J13: =lt_sl!F30 -> 2.5 | K13: =lt_sl!K30 -> 38.69 | L13: =H13^F13 -> 0.98374643 | M13: =1-L13 -> 0.01625357 | N13: =N12*L12 -> 95216.242 | O13: =N13*M13 -> 1547.6039 | P13: =(((-5/24)*O12)+((2.5)*O13)+((5/24)*O14))/O13 -> 2.6324056 | Q13: =(C13*N14)+(P13*O13) -> 472417.11 | R13: =R14+Q13 -> 3716074.4 | S13: =R13/N13 -> 39.027737 | T13: =S13-K13 -> 0.33773682
B14: 45 | C14: 5 | D14: =def_sl!D31 -> 385.57353 | E14: =def_pro_homicidios_sl!D434 -> 31.134783 | F14: =(D14-E14)/D14 -> 0.91925073 | G14: =lt_sl!G31 -> 92070 | H14: =1-lt_sl!E31 -> 0.975933 | I14: =1-H14 -> 0.024067 | J14: =lt_sl!F31 -> 2.5 | K14: =lt_sl!K31 -> 34.38 | L14: =H14^F14 -> 0.97785471 | M14: =1-L14 -> 0.022145293 | N14: =N13*L13 -> 93668.638 | O14: =N14*M14 -> 2074.3195 | P14: =(((-5/24)*O13)+((2.5)*O14)+((5/24)*O15))/O14 -> 2.6442297 | Q14: =(C14*N15)+(P14*O14) -> 463456.57 | R14: =R15+Q14 -> 3243657.3 | S14: =R14/N14 -> 34.629065 | T14: =S14-K14 -> 0.2490646
B15: 50 | C15: 5 | D15: =def_sl!D32 -> 502.59617 | E15: =def_pro_homicidios_sl!D435 -> 33.143478 | F15: =(D15-E15)/D15 -> 0.93405545 | G15: =lt_sl!G32 -> 89854 | H15: =1-lt_sl!E32 -> 0.965166 | I15: =1-H15 -> 0.034834 | J15: =lt_sl!F32 -> 2.5 | K15: =lt_sl!K32 -> 30.16 | L15: =H15^F15 -> 0.96742527 | M15: =1-L15 -> 0.032574729 | N15: =N14*L14 -> 91594.319 | O15: =N15*M15 -> 2983.6601 | P15: =(((-5/24)*O14)+((2.5)*O15)+((5/24)*O16))/O15 -> 2.6509415 | Q15: =(C15*N16)+(P15*O15) -> 450962.8 | R15: =R16+Q15 -> 2780200.7 | S15: =R15/N15 -> 30.353419 | T15: =S15-K15 -> 0.1934192
B16: 55 | C16: 5 | D16: =def_sl!D33 -> 583.11109 | E16: =def_pro_homicidios_sl!D436 -> 16.069565 | F16: =(D16-E16)/D16 -> 0.97244167 | G16: =lt_sl!G33 -> 86724 | H16: =1-lt_sl!E33 -> 0.950874 | I16: =1-H16 -> 0.049126 | J16: =lt_sl!F33 -> 2.5 | K16: =lt_sl!K33 -> 26.16 | L16: =H16^F16 -> 0.95219493 | M16: =1-L16 -> 0.047805065 | N16: =N15*L15 -> 88610.658 | O16: =N16*M16 -> 4236.0383 | P16: =(((-5/24)*O15)+((2.5)*O16)+((5/24)*O17))/O16 -> 2.6121716 | Q16: =(C16*N17)+(P16*O16) -> 432938.36 | R16: =R17+Q16 -> 2329237.9 | S16: =R16/N16 -> 26.286205 | T16: =S16-K16 -> 0.12620516
B17: 60 | C17: 5 | D17: =def_sl!D34 -> 648.62325 | E17: =def_pro_homicidios_sl!D437 -> 9.0391304 | F17: =(D17-E17)/D17 -> 0.98606413 | G17: =lt_sl!G34 -> 82464 | H17: =1-lt_sl!E34 -> 0.936753 | I17: =1-H17 -> 0.063247 | J17: =lt_sl!F34 -> 2.5 | K17: =lt_sl!K34 -> 22.38 | L17: =H17^F17 -> 0.93760631 | M17: =1-L17 -> 0.062393689 | N17: =N16*L16 -> 84374.62 | O17: =N17*M17 -> 5264.4438 | P17: =(((-5/24)*O16)+((2.5)*O17)+((5/24)*O18))/O17 -> 2.6068719 | Q17: =(C17*N18)+(P17*O17) -> 409274.61 | R17: =R18+Q17 -> 1896299.6 | S17: =R17/N17 -> 22.474763 | T17: =S17-K17 -> 0.094762963
B18: 65 | C18: 5 | D18: =def_sl!D35 -> 709.13376 | E18: =def_pro_homicidios_sl!D438 -> 8.0347826 | F18: =(D18-E18)/D18 -> 0.98866958 | G18: =lt_sl!G35 -> 77248 | H18: =1-lt_sl!E35 -> 0.911358 | I18: =1-H18 -> 0.088642 | J18: =lt_sl!F35 -> 2.5 | K18: =lt_sl!K35 -> 18.72 | L18: =H18^F18 -> 0.91231696 | M18: =1-L18 -> 0.087683036 | N18: =N17*L17 -> 79110.176 | O18: =N18*M18 -> 6936.6204 | P18: =(((-5/24)*O17)+((2.5)*O18)+((5/24)*O19))/O18 -> 2.6212278 | Q18: =(C18*N19)+(P18*O18) -> 379050.24 | R18: =R19+Q18 -> 1487025 | S18: =R18/N18 -> 18.796886 | T18: =S18-K18 -> 0.076886129
B19: 70 | C19: 5 | D19: =def_sl!D36 -> 818.65582 | E19: =def_pro_homicidios_sl!D439 -> 1.0043478 | F19: =(D19-E19)/D19 -> 0.99877317 | G19: =lt_sl!G36 -> 70401 | H19: =1-lt_sl!E36 -> 0.870985 | I19: =1-H19 -> 0.129015 | J19: =lt_sl!F36 -> 2.5 | K19: =lt_sl!K36 -> 15.3 | L19: =H19^F19 -> 0.87113261 | M19: =1-L19 -> 0.12886739 | N19: =N18*L18 -> 72173.556 | O19: =N19*M19 -> 9300.8177 | P19: =(((-5/24)*O18)+((2.5)*O19)+((5/24)*O20))/O19 -> 2.6085396 | Q19: =(C19*N20)+(P19*O19) -> 338625.24 | R19: =R20+Q19 -> 1107974.7 | S19: =R19/N19 -> 15.351533 | T19: =S19-K19 -> 0.05153312
B20: 75 | C20: 5 | D20: =def_sl!D37 -> 908.67464 | E20: =def_pro_homicidios_sl!D440 -> 5.0217391 | F20: =(D20-E20)/D20 -> 0.99447356 | G20: =lt_sl!G37 -> 61318 | H20: =1-lt_sl!E37 -> 0.811665 | I20: =1-H20 -> 0.188335 | J20: =lt_sl!F37 -> 2.5 | K20: =lt_sl!K37 -> 12.2 | L20: =H20^F20 -> 0.81260154 | M20: =1-L20 -> 0.18739846 | N20: =N19*L19 -> 62872.738 | O20: =N20*M20 -> 11782.254 | P20: =(((-5/24)*O19)+((2.5)*O20)+((5/24)*O21))/O20 -> 2.5993939 | Q20: =(C20*N21)+(P20*O20) -> 286079.14 | R20: =R21+Q20 -> 769349.49 | S20: =R20/N20 -> 12.236615 | T20: =S20-K20 -> 0.036614997
B21: 80 | C21: 5 | D21: =def_sl!D38 -> 1003.1912 | E21: =def_pro_homicidios_sl!D441 -> 4.0173913 | F21: =(D21-E21)/D21 -> 0.99599539 | G21: =lt_sl!G38 -> 49770 | H21: =1-lt_sl!E38 -> 0.706947 | I21: =1-H21 -> 0.293053 | J21: =lt_sl!F38 -> 2.5 | K21: =lt_sl!K38 -> 9.45 | L21: =H21^F21 -> 0.70792949 | M21: =1-L21 -> 0.29207051 | N21: =N20*L20 -> 51090.484 | O21: =N21*M21 -> 14922.024 | P21: =C21+(F21*(I21/M21)*(J21-C21)) -> 2.5016355 | Q21: =(C21*N22)+(P21*O21) -> 218171.77 | R21: =R22+Q21 -> 483270.35 | S21: =R21/N21 -> 9.4591069 | T21: =S21-K21 -> 0.0091068999
B22: 85 | C22: 5 | D22: =def_sl!D39 -> 1802.3391 | E22: =def_pro_homicidios_sl!D442 -> 3.0130435 | F22: =(D22-E22)/D22 -> 0.99832826 | G22: =lt_sl!G39 -> 35184 | H22: =1-lt_sl!E39 -> 0 | I22: =1-H22 -> 1 | J22: =lt_sl!F39 -> NA | K22: =lt_sl!K39 -> 7.33 | L22: =H22^F22 -> 0 | M22: =1-L22 -> 1 | N22: =N21*L21 -> 36168.46 | O22: =N22*M22 -> 36168.46 | P22: =K22/F22 -> 7.3422744 | Q22: =N22/lt_sl!D39 -> 265098.58 | R22: =Q22 -> 265098.58 | S22: =R22/N22 -> 7.3295513 | T22: =S22-K22 -> -0.00044871513
B24: Mujeres, 2019
B26: Age x | C26: n | D26: nDx | E26: nDxi | I26: nqx | K26: e0 | M26: nqx_i | O26: ndx_i | Q26: L | R26: T | S26: e0_i | T26: diff | AA26: Hombres | AB26: Mujeres
B27: 0 | C27: 1 | D27: =def_sl!D97 -> 202.72792 | E27: =def_pro_homicidios_sl!D902 -> 0 | F27: =(D27-E27)/D27 -> 1 | G27: =lt_sl!G78 -> 100000 | H27: =1-lt_sl!E78 -> 0.998515 | I27: =1-H27 -> 0.001485 | J27: =lt_sl!F78 -> 0.06 | K27: =lt_sl!K78 -> 80.9 | L27: =H27^F27 -> 0.998515 | M27: =1-L27 -> 0.001485 | N27: 100000 | O27: =N27*M27 -> 148.5 | P27: =C27+(F27*(I27/M27)*(J27-C27)) -> 0.06 | Q27: =(C27*N28)+(P27*O27) -> 99860.41 | R27: =R28+Q27 -> 8106708 | S27: =R27/N27 -> 81.06708 | T27: =S27-K27 -> 0.16708049 | Z27: Sin homicidios | AA27: =S4 -> 76.478821 | AB27: =S27 -> 81.06708
B28: 1 | C28: 4 | D28: =def_sl!D98 -> 44.008463 | E28: =def_pro_homicidios_sl!D903 -> 1.0204082 | F28: =(D28-E28)/D28 -> 0.97681337 | G28: =lt_sl!G79 -> 99852 | H28: =1-lt_sl!E79 -> 0.998126 | I28: =1-H28 -> 0.001874 | J28: =lt_sl!F79 -> 1.52 | K28: =lt_sl!K79 -> 80.02 | L28: =H28^F28 -> 0.99816941 | M28: =1-L28 -> 0.001830588 | N28: =N27*L27 -> 99851.5 | O28: =N28*M28 -> 182.78696 | P28: =C28+(F28*(I28/M28)*(J28-C28)) -> 1.5200539 | Q28: =(C28*N29)+(P28*O28) -> 398952.7 | R28: =R29+Q28 -> 8006847.6 | S28: =R28/N28 -> 80.187555 | T28: =S28-K28 -> 0.16755491 | V28: Número de años que se espera que viva una mujer de 0 años hasta llegar a los 85 años. | Z28: Con homicidios | AA28: =K4 -> 75.44 | AB28: =K27 -> 80.9
B29: 5 | C29: 5 | D29: =def_sl!D99 -> 24.003385 | E29: 0 | F29: =(D29-E29)/D29 -> 1 | G29: =lt_sl!G80 -> 99664 | H29: =1-lt_sl!E80 -> 0.999006 | I29: =1-H29 -> 0.000994 | J29: =lt_sl!F80 -> 2.5 | K29: =lt_sl!K80 -> 76.17 | L29: =H29^F29 -> 0.999006 | M29: =1-L29 -> 0.000994 | N29: =N28*L28 -> 99668.713 | O29: =N29*M29 -> 99.070701 | P29: =C29+(F29*(I29/M29)*(J29-C29)) -> 2.5 | Q29: =(C29*N30)+(P29*O29) -> 498095.89 | R29: =R30+Q29 -> 7607894.9 | S29: =R29/N29 -> 76.331827 | T29: =S29-K29 -> 0.1618268 | AA29: =AA27-AA28 -> 1.0388215 | AB29: =AB27-AB28 -> 0.16708049
B30: 10 | C30: 5 | D30: =def_sl!D100 -> 33.506263 | E30: =def_pro_homicidios_sl!D904 -> 2.0408163 | F30: =(D30-E30)/D30 -> 0.9390915 | G30: =lt_sl!G81 -> 99565 | H30: =1-lt_sl!E81 -> 0.998662 | I30: =1-H30 -> 0.001338 | J30: =lt_sl!F81 -> 2.5 | K30: =lt_sl!K81 -> 71.24 | L30: =H30^F30 -> 0.99874344 | M30: =1-L30 -> 0.0012565556 | N30: =N29*L29 -> 99569.642 | O30: =N30*M30 -> 125.1148 | P30: =(((-5/24)*O29)+((2.5)*O30)+((5/24)*O31))/O30 -> 2.648124 | Q30: =(C30*N31)+(P30*O30) -> 497553.96 | R30: =R31+Q30 -> 7109799.1 | S30: =R30/N30 -> 71.405289 | T30: =S30-K30 -> 0.16528866
B31: 15 | C31: 5 | D31: =def_sl!D101 -> 56.010325 | E31: =def_pro_homicidios_sl!D905 -> 8.1632653 | F31: =(D31-E31)/D31 -> 0.85425428 | G31: =lt_sl!G82 -> 99432 | H31: =1-lt_sl!E82 -> 0.997787 | I31: =1-H31 -> 0.002213 | J31: =lt_sl!F82 -> 2.5 | K31: =lt_sl!K82 -> 66.33 | L31: =H31^F31 -> 0.99810923 | M31: =1-L31 -> 0.0018907698 | N31: =N30*L30 -> 99444.528 | O31: =N31*M31 -> 188.02671 | P31: =(((-5/24)*O30)+((2.5)*O31)+((5/24)*O32))/O31 -> 2.5973717 | Q31: =(C31*N32)+(P31*O31) -> 496770.88 | R31: =R32+Q31 -> 6612245.1 | S31: =R31/N31 -> 66.491795 | T31: =S31-K31 -> 0.16179456 | V31: Sin COVID | W31: Con COVID
B32: 20 | C32: 5 | D32: =def_sl!D102 -> 59.009818 | E32: =def_pro_homicidios_sl!D906 -> 8.1632653 | F32: =(D32-E32)/D32 -> 0.86166259 | G32: =lt_sl!G83 -> 99212 | H32: =1-lt_sl!E83 -> 0.99751 | I32: =1-H32 -> 0.00249 | J32: =lt_sl!F83 -> 2.5 | K32: =lt_sl!K83 -> 61.47 | L32: =H32^F32 -> 0.99785409 | M32: =1-L32 -> 0.0021459097 | N32: =N31*L31 -> 99256.501 | O32: =N32*M32 -> 212.99549 | P32: =(((-5/24)*O31)+((2.5)*O32)+((5/24)*O33))/O32 -> 2.5936966 | Q32: =(C32*N33)+(P32*O32) -> 495769.97 | R32: =R33+Q32 -> 6115474.2 | S32: =R32/N32 -> 61.612833 | T32: =S32-K32 -> 0.14283306 | V32: =([1]TV!M29-[1]TV!M47)/[1]TV!J29 -> 73.3257 | W32: =(R27-R45)/N27 -> 77.39721
B33: 25 | C33: 5 | D33: =def_sl!D103 -> 73.512187 | E33: =def_pro_homicidios_sl!D907 -> 8.1632653 | F33: =(D33-E33)/D33 -> 0.88895358 | G33: =lt_sl!G84 -> 98965 | H33: =1-lt_sl!E84 -> 0.996777 | I33: =1-H33 -> 0.003223 | J33: =lt_sl!F84 -> 2.5 | K33: =lt_sl!K84 -> 56.62 | L33: =H33^F33 -> 0.99713439 | M33: =1-L33 -> 0.0028656107 | N33: =N32*L32 -> 99043.505 | O33: =N33*M33 -> 283.82013 | P33: =(((-5/24)*O32)+((2.5)*O33)+((5/24)*O34))/O33 -> 2.5876882 | Q33: =(C33*N34)+(P33*O33) -> 494532.86 | R33: =R34+Q33 -> 5619704.2 | S33: =R33/N33 -> 56.739755 | T33: =S33-K33 -> 0.11975516 | V33: Diff | W33: =W32-V32 -> 4.0715098
B34: 30 | C34: 5 | D34: =def_sl!D104 -> 76.010325 | E34: =def_pro_homicidios_sl!D908 -> 4.0816327 | F34: =(D34-E34)/D34 -> 0.9463016 | G34: =lt_sl!G85 -> 98646 | H34: =1-lt_sl!E85 -> 0.996443 | I34: =1-H34 -> 0.003557 | J34: =lt_sl!F85 -> 2.5 | K34: =lt_sl!K85 -> 51.8 | L34: =H34^F34 -> 0.99663368 | M34: =1-L34 -> 0.0033663167 | N34: =N33*L33 -> 98759.685 | O34: =N34*M34 -> 332.45637 | P34: =(((-5/24)*O33)+((2.5)*O34)+((5/24)*O35))/O34 -> 2.6321344 | Q34: =(C34*N35)+(P34*O34) -> 493011.21 | R34: =R35+Q34 -> 5125171.4 | S34: =R34/N34 -> 51.89538 | T34: =S34-K34 -> 0.095379868
B35: 35 | C35: 5 | D35: =def_sl!D105 -> 108.51794 | E35: =def_pro_homicidios_sl!D909 -> 7.1428571 | F35: =(D35-E35)/D35 -> 0.9341781 | G35: =lt_sl!G86 -> 98295 | H35: =1-lt_sl!E86 -> 0.994621 | I35: =1-H35 -> 0.005379 | J35: =lt_sl!F86 -> 2.5 | K35: =lt_sl!K86 -> 46.97 | L35: =H35^F35 -> 0.99497416 | M35: =1-L35 -> 0.0050258353 | N35: =N34*L34 -> 98427.229 | O35: =N35*M35 -> 494.67904 | P35: =(((-5/24)*O34)+((2.5)*O35)+((5/24)*O36))/O35 -> 2.7183984 | Q35: =(C35*N36)+(P35*O35) -> 491007.48 | R35: =R36+Q35 -> 4632160.2 | S35: =R35/N35 -> 47.061776 | T35: =S35-K35 -> 0.091775693
B36: 40 | C36: 5 | D36: =def_sl!D106 -> 164.53013 | E36: =def_pro_homicidios_sl!D910 -> 1.0204082 | F36: =(D36-E36)/D36 -> 0.99379805 | G36: =lt_sl!G87 -> 97766 | H36: =1-lt_sl!E87 -> 0.991256 | I36: =1-H36 -> 0.008744 | J36: =lt_sl!F87 -> 2.5 | K36: =lt_sl!K87 -> 42.21 | L36: =H36^F36 -> 0.99130999 | M36: =1-L36 -> 0.0086900064 | N36: =N35*L35 -> 97932.55 | O36: =N36*M36 -> 851.03449 | P36: =(((-5/24)*O35)+((2.5)*O36)+((5/24)*O37))/O36 -> 2.6821808 | Q36: =(C36*N37)+(P36*O36) -> 487690.2 | R36: =R37+Q36 -> 4141152.7 | S36: =R36/N36 -> 42.285764 | T36: =S36-K36 -> 0.07576393
B37: 45 | C37: 5 | D37: =def_sl!D107 -> 225.03859 | E37: =def_pro_homicidios_sl!D911 -> 1.0204082 | F37: =(D37-E37)/D37 -> 0.99546563 | G37: =lt_sl!G88 -> 96912 | H37: =1-lt_sl!E88 -> 0.987181 | I37: =1-H37 -> 0.012819 | J37: =lt_sl!F88 -> 2.5 | K37: =lt_sl!K88 -> 37.56 | L37: =H37^F37 -> 0.98723875 | M37: =1-L37 -> 0.012761246 | N37: =N36*L36 -> 97081.515 | O37: =N37*M37 -> 1238.8811 | P37: =(((-5/24)*O36)+((2.5)*O37)+((5/24)*O38))/O37 -> 2.6439956 | Q37: =(C37*N38)+(P37*O37) -> 482488.77 | R37: =R38+Q37 -> 3653462.5 | S37: =R37/N37 -> 37.632936 | T37: =S37-K37 -> 0.072936252
B38: 50 | C38: 5 | D38: =def_sl!D108 -> 287.54976 | E38: =def_pro_homicidios_sl!D912 -> 2.0408163 | F38: =(D38-E38)/D38 -> 0.99290274 | G38: =lt_sl!G89 -> 95669 | H38: =1-lt_sl!E89 -> 0.98206 | I38: =1-H38 -> 0.01794 | J38: =lt_sl!F89 -> 2.5 | K38: =lt_sl!K89 -> 33.02 | L38: =H38^F38 -> 0.98218618 | M38: =1-L38 -> 0.017813816 | N38: =N37*L37 -> 95842.634 | O38: =N38*M38 -> 1707.323 | P38: =(((-5/24)*O37)+((2.5)*O38)+((5/24)*O39))/O38 -> 2.7153189 | Q38: =(C38*N39)+(P38*O38) -> 475312.48 | R38: =R39+Q38 -> 3170973.7 | S38: =R38/N38 -> 33.08521 | T38: =S38-K38 -> 0.065210326
B39: 55 | C39: 5 | D39: =def_sl!D109 -> 422.07211 | E39: =def_pro_homicidios_sl!D913 -> 3.0612245 | F39: =(D39-E39)/D39 -> 0.99274715 | G39: =lt_sl!G90 -> 93953 | H39: =1-lt_sl!E90 -> 0.967865 | I39: =1-H39 -> 0.032135 | J39: =lt_sl!F90 -> 2.5 | K39: =lt_sl!K90 -> 28.57 | L39: =H39^F39 -> 0.96809431 | M39: =1-L39 -> 0.031905688 | N39: =N38*L38 -> 94135.311 | O39: =N39*M39 -> 3003.4519 | P39: =(((-5/24)*O38)+((2.5)*O39)+((5/24)*O40))/O39 -> 2.6634022 | Q39: =(C39*N40)+(P39*O39) -> 463658.7 | R39: =R40+Q39 -> 2695661.2 | S39: =R39/N39 -> 28.636026 | T39: =S39-K39 -> 0.066026114
B40: 60 | C40: 5 | D40: =def_sl!D110 -> 501.58819 | E40: =def_pro_homicidios_sl!D914 -> 0 | F40: =(D40-E40)/D40 -> 1 | G40: =lt_sl!G91 -> 90934 | H40: =1-lt_sl!E91 -> 0.955416 | I40: =1-H40 -> 0.044584 | J40: =lt_sl!F91 -> 2.5 | K40: =lt_sl!K91 -> 24.44 | L40: =H40^F40 -> 0.955416 | M40: =1-L40 -> 0.044584 | N40: =N39*L39 -> 91131.859 | O40: =N40*M40 -> 4063.0228 | P40: =(((-5/24)*O39)+((2.5)*O40)+((5/24)*O41))/O40 -> 2.6404836 | Q40: =(C40*N41)+(P40*O40) -> 446072.53 | R40: =R41+Q40 -> 2232002.5 | S40: =R40/N40 -> 24.492011 | T40: =S40-K40 -> 0.052011352
B41: 65 | C41: 5 | D41: =def_sl!D111 -> 570.60224 | E41: =def_pro_homicidios_sl!D915 -> 0 | F41: =(D41-E41)/D41 -> 1 | G41: =lt_sl!G92 -> 86880 | H41: =1-lt_sl!E92 -> 0.934038 | I41: =1-H41 -> 0.065962 | J41: =lt_sl!F92 -> 2.5 | K41: =lt_sl!K92 -> 20.46 | L41: =H41^F41 -> 0.934038 | M41: =1-L41 -> 0.065962 | N41: =N40*L40 -> 87068.836 | O41: =N41*M41 -> 5743.2346 | P41: =(((-5/24)*O40)+((2.5)*O41)+((5/24)*O42))/O41 -> 2.6499496 | Q41: =(C41*N42)+(P41*O41) -> 421847.29 | R41: =R42+Q41 -> 1785930 | S41: =R41/N41 -> 20.511702 | T41: =S41-K41 -> 0.051701742
B42: 70 | C42: 5 | D42: =def_sl!D112 -> 689.61781 | E42: =def_pro_homicidios_sl!D916 -> 1.0204082 | F42: =(D42-E42)/D42 -> 0.99852033 | G42: =lt_sl!G93 -> 81149 | H42: =1-lt_sl!E93 -> 0.899069 | I42: =1-H42 -> 0.100931 | J42: =lt_sl!F93 -> 2.5 | K42: =lt_sl!K93 -> 16.73 | L42: =H42^F42 -> 0.89921055 | M42: =1-L42 -> 0.10078945 | N42: =N41*L41 -> 81325.602 | O42: =N42*M42 -> 8196.7625 | P42: =(((-5/24)*O41)+((2.5)*O42)+((5/24)*O43))/O42 -> 2.642388 | Q42: =(C42*N43)+(P42*O42) -> 387303.22 | R42: =R43+Q42 -> 1364082.7 | S42: =R42/N42 -> 16.773103 | T42: =S42-K42 -> 0.043103199
B43: 75 | C43: 5 | D43: =def_sl!D113 -> 781.63321 | E43: =def_pro_homicidios_sl!D917 -> 1.0204082 | F43: =(D43-E43)/D43 -> 0.99869452 | G43: =lt_sl!G94 -> 72958 | H43: =1-lt_sl!E94 -> 0.844671 | I43: =1-H43 -> 0.155329 | J43: =lt_sl!F94 -> 2.5 | K43: =lt_sl!K94 -> 13.33 | L43: =H43^F43 -> 0.84485717 | M43: =1-L43 -> 0.15514283 | N43: =N42*L42 -> 73128.839 | O43: =N43*M43 -> 11345.415 | P43: =(((-5/24)*O42)+((2.5)*O43)+((5/24)*O44))/O43 -> 2.6276 | Q43: =(C43*N44)+(P43*O43) -> 338728.33 | R43: =R44+Q43 -> 976779.49 | S43: =R43/N43 -> 13.356967 | T43: =S43-K43 -> 0.026966931
...

Sheet lt_sl
A1: year | B1: sex | C1: age | D1: mx | E1: qx | F1: ax | G1: lx | H1: dx | I1: Lx.1 | J1: Tx | K1: ex
A2: 2010 | B2: m | C2: 0 | D2: 0.00196 | E2: 0.001956 | F2: 0.05 | G2: 100000 | H2: 196 | I2: 99814 | J2: 7595102 | K2: 75.95
A3: 2010 | B3: m | C3: 1 | D3: 0.000607 | E3: 0.002426 | F3: 1.65 | G3: 99804 | H3: 242 | I3: 398648 | J3: 7495288 | K3: 75.1
A4: 2010 | B4: m | C4: 5 | D4: 0.000226 | E4: 0.00113 | F4: 2.5 | G4: 99562 | H4: 113 | I4: 497530 | J4: 7096641 | K4: 71.28
A5: 2010 | B5: m | C5: 10 | D5: 0.000376 | E5: 0.001879 | F5: 2.5 | G5: 99450 | H5: 187 | I5: 496782 | J5: 6599110 | K5: 66.36
A6: 2010 | B6: m | C6: 15 | D6: 0.001046 | E6: 0.005216 | F6: 2.5 | G6: 99263 | H6: 518 | I6: 495020 | J6: 6102329 | K6: 61.48
A7: 2010 | B7: m | C7: 20 | D7: 0.001699 | E7: 0.008461 | F7: 2.5 | G7: 98745 | H7: 836 | I7: 491637 | J7: 5607309 | K7: 56.79
A8: 2010 | B8: m | C8: 25 | D8: 0.002126 | E8: 0.010574 | F8: 2.5 | G8: 97910 | H8: 1035 | I8: 486960 | J8: 5115672 | K8: 52.25
A9: 2010 | B9: m | C9: 30 | D9: 0.002165 | E9: 0.010766 | F9: 2.5 | G9: 96874 | H9: 1043 | I9: 481764 | J9: 4628712 | K9: 47.78
A10: 2010 | B10: m | C10: 35 | D10: 0.002727 | E10: 0.013543 | F10: 2.5 | G10: 95831 | H10: 1298 | I10: 475912 | J10: 4146948 | K10: 43.27
A11: 2010 | B11: m | C11: 40 | D11: 0.003453 | E11: 0.017115 | F11: 2.5 | G11: 94534 | H11: 1618 | I11: 468623 | J11: 3671036 | K11: 38.83
A12: 2010 | B12: m | C12: 45 | D12: 0.004565 | E12: 0.022569 | F12: 2.5 | G12: 92916 | H12: 2097 | I12: 459335 | J12: 3202413 | K12: 34.47
A13: 2010 | B13: m | C13: 50 | D13: 0.006608 | E13: 0.032501 | F13: 2.5 | G13: 90819 | H13: 2952 | I13: 446714 | J13: 2743078 | K13: 30.2
... A115: 2021 | B115: f | C115: 85 | D115: 0.142736 | E115: 1 | F115: NA | G115: 34375 | H115: 34375 | I115: 240832 | J115: 240832 | K115: 7.01

Sheet def_sl
A1: year | B1: sex | C1: age | D1: deaths
A2: 2010 | B2: male | C2: 0 | D2: 292.12328
A3: 2010 | B3: male | C3: 1 | D3: 61.845082
A4: 2010 | B4: male | C4: 5 | D4: 30.752604
A5: 2010 | B5: male | C5: 10 | D5: 51.472732
A6: 2010 | B6: male | C6: 15 | D6: 141.40551
A7: 2010 | B7: male | C7: 20 | D7: 179.49931
A8: 2010 | B8: male | C8: 25 | D8: 187.84217
A9: 2010 | B9: male | C9: 30 | D9: 182.84754
A10: 2010 | B10: male | C10: 35 | D10: 225.9778
A11: 2010 | B11: male | C11: 40 | D11: 248.04773
A12: 2010 | B12: male | C12: 45 | D12: 282.80894
A13: 2010 | B13: male | C13: 50 | D13: 354.34008
... A153: 2022 | B153: female | C153: 85 | D153: 2508.567

Sheet def_pro_homicidios_sl
A1: year | B1: sex | C1: age | D1: deaths
A2: 1990 | B2: male | C2: 0 | D2: 1.0230415
A3: 1990 | B3: male | C3: 1 | D3: 1.0230415
A4: 1990 | B4: male | C4: 10 | D4: 4.0921659
A5: 1990 | B5: male | C5: 15 | D5: 33.760369
A6: 1990 | B6: male | C6: 20 | D6: 26.599078
A7: 1990 | B7: male | C7: 25 | D7: 30.691244
A8: 1990 | B8: male | C8: 30 | D8: 22.506912
A9: 1990 | B9: male | C9: 35 | D9: 27.62212
A10: 1990 | B10: male | C10: 40 | D10: 14.322581
A11: 1990 | B11: male | C11: 45 | D11: 15.345622
A12: 1990 | B12: male | C12: 50 | D12: 11.253456
A13: 1990 | B13: male | C13: 55 | D13: 11.253456
... A955: 2022 | B955: female | C955: 85 | D955: 0
